Workbook

Sheet Resumen por Persona
A1: Asignación de Cuentas por Persona
A2: Total de Personas: 78 | Consolidado desde 'Rentabilidad_x_Cuentas.csv'
A4: Persona | B4: Cantidad de Cuentas | C4: Cuentas Asignadas
A5: Bitar Maluk Maria Cristina | B5: 31 | C5: ACLARA, AES ANDES, AFPs, AGUAS ANDINAS, ALTO MAIPO SPA, APPLE, Aguas Horizonte, BANCO SANTANDER, BHP, Bupa, CHEC, CHINA RAILWAY (CRCCI), COCA COLA, COMUNIDAD MUJER, DREAMS, Equinox, GIA, Gestión Azerta, Metlife, Metrogas, NESTLE, ONU Chile (Proyecto por una sola vez), Pluxee, Propuestas, Rio Tinto, SURALIS, Securiport, Silver Sea, TRANSELEC, Todoplay, WOM
A6: Flores Vargas Miguel Luis | B6: 23 | C6: AFP Capital, BHP, BOW (Proyecto), CAP, CENCOSUD, COCA COLA, COLUN, DOMINGA, Exxacon, HANCOCK, IFPI, Inmobiliaria Manquehue, MASTERCARD, Mantos Blancos, Marimaca, Metrogas, Propuestas, RED UC, SQM / Novandino, Securiport, Silver Sea, TRANSELEC, Terra Master
A7: Edwards Marin Felipe | B7: 21 | C7: ABIF, ACER, ACLARA, AFP Capital, ALGECIRAS, Australis, BANCO SANTANDER, CAP, CENCOSUD, COLUN, DOMINGA, EMPRESAS PENTA, Grupo Patio, Marimaca, Metrogas, Orion X, Puerto Coronel, SCHWAGER, Techint, ULTRAMAR, ULTRANAV
A8: Arancibia Silva Jose Miguel | B8: 16 | C8: ABIF, ACLARA, Australis, Azerta, BHP, CAP, CENCOSUD, CHINA RAILWAY (CRCCI), CRUZADOS, Colmena, DOMINGA, Gestión Azerta, Mutual, NISUM, Propuestas, SCANIA
A9: Burr Guarachi Maria Victoria | B9: 14 | C9: BHP, Colmena, ECHEVERRÍA IZQUIERDO (PROYECTO), Equinox, GRUPO COSTANERA, Gestión Azerta, Inmobiliaria Manquehue, MEDICINA UC, Marimaca, Mutual, RED UC, Teck, Todoplay, ZONA FRANCA
A10: Mackinnon Nilo Ian Eduardo | B10: 13 | C10: APPLE, BANMEDICA, COCA COLA, Candidaturas Chile, Deficit 0, Electrolux, HANCOCK, MASTERCARD, Mutual, Propuestas, SQM Yodo, SURALIS, WOM
A11: Abarca Castro Juan Andres | B11: 12 | C11: APPLE, Aguas Horizonte, Azerta, BANMEDICA, BHP, Congreso, Marimaca, Mutual, SQM Yodo, Securiport, Silver Sea, Teck
A12: Galleguillos Martinez Luis Gustavo | B12: 12 | C12: AES ANDES, ALTO MAIPO SPA, Aguas Horizonte, Australis, CHEC, FREEPORT EL ABRA, Fray Leon Family Office (2 meses), Gestión Azerta, Propuestas, Puerto Coronel, Talleres de Vocería, ULTRANAV
A13: Padilla Castellano Reimar Coromoto | B13: 12 | C13: AGUAS ANDINAS, Aguas Horizonte, BHP, CIAL, Colmena, Equinox, GRUPO COSTANERA, Grupo Patio, Inmobiliaria Manquehue, Metrogas, Mutual, Todoplay
A14: Calderon Ventura Alfonso | B14: 11 | C14: AFPs, BANCO SANTANDER, BOW (Proyecto), COCA COLA, Candidaturas Chile, Colmena, Electrolux, Equinox, HANCOCK, Permisología, RED UC
A15: Soto Díaz Javiera Paz | B15: 11 | C15: AFPs, Bupa, CENCOSUD, COCA COLA, Colmena, Congreso, GIA, IFPI, Pluxee, RED UC, Todoplay
A16: Delgado Tornero Felipe Antonio | B16: 10 | C16: BHP, CAP, DOMINGA, DREAMS, FREEPORT EL ABRA, Marimaca, NISUM, Puerto Coronel, Rio Tinto, ULTRANAV
... A60: Vallejos Poblete Carlos Jose | B60: 5 | C60: AGUAS ANDINAS, Aguas Horizonte, Pluxee, Rio Tinto, WOM
A61: Total Personas / Promedio Cuentas | B61: =AVERAGE(B1:B60) -> 8.5714286
A62: Alcaino Cueto Nieves Isabel | B62: 4 | C62: AFP Cuprum, CHINA RAILWAY (CRCCI), GIA, TRANSELEC
A63: Alvarez Rivera Romina Pamela | B63: 4 | C63: CENCOSUD, CIAL, NESTLE, WOM
A64: Cobo Paris Irene María | B64: 4 | C64: Azerta, ESG, Grupo Patio, Mutual
A65: Herrera Manríquez María Fernanda | B65: 4 | C65: ABIF, AFP Capital, CAP, COMUNIDAD MUJER
A66: Mackenzie Kiessler Paula | B66: 4 | C66: AFP Capital, Colmena, Grupo Patio, Metrogas
A67: Martínez Cárdenas Natalia Paulina | B67: 4 | C67: CAP, Mutual, SCANIA, SCHWAGER
A68: Martínez Medel María Paz | B68: 4 | C68: BHP, CENCOSUD, DOMINGA, Mutual
A69: Muñoz Orellana Liliana Andrea | B69: 4 | C69: CENCOSUD, Equinox, SURALIS, WOM
A70: Palomino Marchant Elisa Eliana | B70: 4 | C70: AES ANDES, CENCOSUD, NESTLE, STARKEN
A71: Sherling Carvallo Yael Rossi | B71: 4 | C71: BANCO SANTANDER, DREAMS, Mutual, NESTLE
A72: Valladares Aravena Javiera Fernanda | B72: 4 | C72: Colmena, DOMINGA, Mutual, SCANIA
A73: Varas Salamanca Mauricio | B73: 4 | C73: AES ANDES, ALTO MAIPO SPA, Mutual, TRANSELEC
... A83: Walmsley Hardy Alexander James | B83: 1 | C83: Gestión Azerta

Sheet Detalle Cuenta-Persona
A1: Detalle Unipersonal por Cuenta
A3: Cuenta / Cliente | B3: Persona | C3: Hrs. X Semana | D3: Rut | E3: Apodo | F3: Cargo | G3: Nivel de Cargo
A4: ABIF | B4: Acuña Gutiérrez Sandra Gabriela | D4: =+VLOOKUP(B4,'Maestro Personas'!$B$7:$C$105,2,0) -> 19.300.070-3 | E4: =+VLOOKUP(B4,'Maestro Personas'!$B$7:$W$105,22,0) -> Sandra | F4: =+VLOOKUP(B4,'Maestro Personas'!$B$7:$G$105,6,0) -> Consultores - Digital
A5: ABIF | B5: Arancibia Silva Jose Miguel | D5: =+VLOOKUP(B5,'Maestro Personas'!$B$7:$C$105,2,0) -> 16.282.327-2 | E5: =+VLOOKUP(B5,'Maestro Personas'!$B$7:$W$105,22,0) -> Jose, JM | F5: =+VLOOKUP(B5,'Maestro Personas'!$B$7:$G$105,6,0) -> Socio Área Digital
A6: ABIF | B6: Domínguez Kopecky Alicia María | D6: =+VLOOKUP(B6,'Maestro Personas'!$B$7:$C$105,2,0) -> 27.028.873-1 | E6: =+VLOOKUP(B6,'Maestro Personas'!$B$7:$W$105,22,0) -> Ali o Alice | F6: =+VLOOKUP(B6,'Maestro Personas'!$B$7:$G$105,6,0) -> Consultores Senior - Digital
A7: ABIF | B7: Edwards Marin Felipe | D7: =+VLOOKUP(B7,'Maestro Personas'!$B$7:$C$105,2,0) -> 10.818.275-k | E7: =+VLOOKUP(B7,'Maestro Personas'!$B$7:$W$105,22,0) -> Felipe | F7: =+VLOOKUP(B7,'Maestro Personas'!$B$7:$G$105,6,0) -> Socio
A8: ABIF | B8: Garrido Corvalan Felipe Josué Andrés | D8: =+VLOOKUP(B8,'Maestro Personas'!$B$7:$C$105,2,0) -> 17.029.247-2 | E8: =+VLOOKUP(B8,'Maestro Personas'!$B$7:$W$105,22,0) -> Felipe | F8: =+VLOOKUP(B8,'Maestro Personas'!$B$7:$G$105,6,0) -> Consultores - Digital
A9: ABIF | B9: González Lira Javiera Ignacia | D9: =+VLOOKUP(B9,'Maestro Personas'!$B$7:$C$105,2,0) -> 19.876.073-0 | E9: =+VLOOKUP(B9,'Maestro Personas'!$B$7:$W$105,22,0) -> Javi | F9: =+VLOOKUP(B9,'Maestro Personas'!$B$7:$G$105,6,0) -> Consultores Senior - Digital
A10: ABIF | B10: Herrera Manríquez María Fernanda | D10: =+VLOOKUP(B10,'Maestro Personas'!$B$7:$C$105,2,0) -> 20.165.239-1 | E10: =+VLOOKUP(B10,'Maestro Personas'!$B$7:$W$105,22,0) -> Fernanda | F10: =+VLOOKUP(B10,'Maestro Personas'!$B$7:$G$105,6,0) -> Consultores - Digital
A11: ABIF | B11: Llanos Guijuelos Bastian Nicolas | D11: =+VLOOKUP(B11,'Maestro Personas'!$B$7:$C$105,2,0) -> 18.172.756-k | E11: =+VLOOKUP(B11,'Maestro Personas'!$B$7:$W$105,22,0) -> Bastián | F11: =+VLOOKUP(B11,'Maestro Personas'!$B$7:$G$105,6,0) -> Consultor/a - Comunicaciones
A12: ABIF | B12: Moreno Soza Javiera Ignacia | D12: =+VLOOKUP(B12,'Maestro Personas'!$B$7:$C$105,2,0) -> 18.956.291-8 | E12: =+VLOOKUP(B12,'Maestro Personas'!$B$7:$W$105,22,0) -> Javi | F12: =+VLOOKUP(B12,'Maestro Personas'!$B$7:$G$105,6,0) -> Ejecutivo/a de Cuentas - Digital
A13: ABIF | B13: Peña Gutiérrez María José | D13: =+VLOOKUP(B13,'Maestro Personas'!$B$7:$C$105,2,0) -> 17.028.885-8 | E13: =+VLOOKUP(B13,'Maestro Personas'!$B$7:$W$105,22,0) -> Mane | F13: =+VLOOKUP(B13,'Maestro Personas'!$B$7:$G$105,6,0) -> Consultor/a Senior - Comunicaciones
A14: ABIF | B14: Saez Rojas Alejandro Enrique | D14: =+VLOOKUP(B14,'Maestro Personas'!$B$7:$C$105,2,0) -> 12.659.237-k | E14: =+VLOOKUP(B14,'Maestro Personas'!$B$7:$W$105,22,0) | F14: =+VLOOKUP(B14,'Maestro Personas'!$B$7:$G$105,6,0) -> Director/a Senior - Comunicaciones
A15: ABIF | B15: Serrano Matas Antonio Federico | D15: =+VLOOKUP(B15,'Maestro Personas'!$B$7:$C$105,2,0) -> 10.321.885-3 | E15: =+VLOOKUP(B15,'Maestro Personas'!$B$7:$W$105,22,0) -> Toño | F15: =+VLOOKUP(B15,'Maestro Personas'!$B$7:$G$105,6,0) -> Consultores Senior - Digital
... A551: ZONA FRANCA | B551: Verdejo Valenzuela Sandra Carolina | D551: =+VLOOKUP(B551,'Maestro Personas'!$B$7:$C$105,2,0) -> 13.038.126-k | E551: =+VLOOKUP(B551,'Maestro Personas'!$B$7:$W$105,22,0) -> Sandra | F551: =+VLOOKUP(B551,'Maestro Personas'!$B$7:$G$105,6,0) -> Consultor/a - Prensa

Sheet Maestro Personas
A1: Libro: Reporte Empleados Datos Contacto Sin Renta | C1: Libro: Reporte Empleados Datos Contacto Sin Renta
A2: Fecha Generación: 04/09/2026 a las 08:30AM | C2: Fecha Generación: 04/09/2026 a las 08:30AM
A3: Fecha Desde: 01/09/2026 | C3: Fecha Desde: 01/09/2026
A4: Fecha Hasta: 04/09/2026 | C4: Fecha Hasta: 04/09/2026
A6: Empleado - Número de Documento | B6: Empleado - Nombre Completo | C6: Empleado - Número de Documento | D6: Empleado - Nombre | E6: Empleado - Apellido | F6: Empleado - Segundo Apellido | G6: Trabajo - Cargo | H6: Trabajo - Nombre División | I6: Empleado - Fecha de Nacimiento | J6: Empleado - Dirección | K6: Empleado - Email | L6: Empleado - Sexo | M6: Empleado - Teléfono Particular | N6: Trabajo - Nombre Sub-área Asignada(o) | O6: Trabajo - Nombre Área | P6: Empresa - RUT Empresa | Q6: Empresa - Nombre Empresa | R6: Empleado - Email Personal | S6: Empleado - Comuna | T6: Empleado - Estado | U6: Empleado - Título | V6: Empleado - Universidad | W6: Campos Personalizados de Empleado - Apodo
A7: 19.939.876-8 | B7: Rivera Montiel Carolina Constanza | C7: 19.939.876-8 | D7: Carolina Constanza | E7: Rivera | F7: Montiel | G7: Ejecutivo/a - AAPP | H7: Asuntos Públicos | I7: 35893 | J7: California 2520, dpto 505 | K7: crivera@azerta.cl | L7: F | M7: 957719640 | N7: Asuntos Públicos | O7: Asuntos Públicos | P7: 76.981.820-0 | Q7: Azerta SpA | R7: carolinarvmn@gmail.com | S7: Providencia | T7: Activo | W7: Caro
A8: 12.454.685-0 | B8: Burr Guarachi Maria Victoria | C8: 12.454.685-0 | D8: Maria Victoria | E8: Burr | F8: Guarachi | G8: Socio Director | H8: Comunicaciones | I8: 26704 | J8: CAMINO LA AGUADA 10341 | K8: vburr@azerta.cl | L8: F | M8: 56997429964 | N8: Comunicaciones | O8: Comunicaciones | P8: 76.981.820-0 | Q8: Azerta SpA | R8: burr.victoria@gmail.com | S8: Lo Barnechea | T8: Activo | W8: Vic
A9: 20.791.630-7 | B9: Ibacache Guzmán Cristofer Ignacio | C9: 20.791.630-7 | D9: Cristofer Ignacio | E9: Ibacache | F9: Guzmán | G9: Ejecutivo de Soporte, Operaciones y TI | H9: Corporate Services | I9: 37366 | J9: Dublé Almeyda 1515, Ñuñoa, Chile | K9: cibacache@azerta.cl | L9: M | M9: 56931866968 | N9: Operaciones | O9: Operaciones | P9: 77.667.011-1 | Q9: SOCIEDAD DE PROFESIONALES AZERTA LTDA | R9: cristofer.ibacacheguz@gmail.com | S9: Ñuñoa | T9: Activo | W9: Cristofer
A10: 19.078.159-3 | B10: Arenas Salgado Margarita Andrea | C10: 19.078.159-3 | D10: Margarita Andrea | E10: Arenas | F10: Salgado | G10: Directora de Estrategia y Desarrollo de Negocio | H10: Corporate Services | I10: 34790 | J10: Pirineos 2002, Providencia, Chile | K10: marenas@azerta.cl | L10: F | M10: 56981584044 | N10: Administración | O10: Administración | P10: 76.981.820-0 | Q10: Azerta SpA | R10: margarita.arenas.salgado@gmail.com | S10: Providencia | T10: Activo | W10: Margarita
A11: 17.950.016-7 | B11: Courtin Díaz Danielle Fernanda | C11: 17.950.016-7 | D11: Danielle Fernanda | E11: Courtin | F11: Díaz | G11: Director/a - AAPP | H11: Asuntos Públicos | I11: 31357 | J11: Noruega 1050, Valparaíso, Chile | K11: dcourtin@azerta.cl | L11: F | M11: 56962753918 | N11: Asuntos Públicos | O11: Asuntos Públicos | P11: 76.981.820-0 | Q11: Azerta SpA | R11: danicourtin@gmail.com | S11: Valparaíso | T11: Activo | W11: Dani
A12: 19.293.473-7 | B12: Casas Irarrázaval Martina Leonor | C12: 19.293.473-7 | D12: Martina Leonor | E12: Casas | F12: Irarrázaval | G12: Consultor/a - Comunicaciones | H12: Comunicaciones | I12: 35335 | J12: Avenida Las Condes 10557, depto. 701 B | K12: mcasas@azerta.cl | L12: F | M12: 981582035 | N12: Comunicaciones | O12: Comunicaciones | P12: 77.667.011-1 | Q12: SOCIEDAD DE PROFESIONALES AZERTA LTDA | R12: mcasasirarrazaval@gmail.com | S12: Las Condes | T12: Activo | W12: Martina
A13: 18.588.568-2 | B13: Orpis Jouanne Ana Luisa | C13: 18.588.568-2 | D13: Ana Luisa | E13: Orpis | F13: Jouanne | G13: Consultor/a - AAPP | H13: Asuntos Públicos | I13: 35216 | J13: Los leones 707 | K13: Aorpis@azerta.cl | L13: F | M13: 953977411 | N13: Asuntos Públicos | O13: Asuntos Públicos | P13: 77.667.011-1 | Q13: SOCIEDAD DE PROFESIONALES AZERTA LTDA | R13: anaorpis@gmail.com | S13: Providencia | T13: Inactivo | W13: Ana
A14: 17.248.821-8 | B14: Martínez Medel María Paz | C14: 17.248.821-8 | D14: María Paz | E14: Martínez | F14: Medel | G14: Ejecutivo/a de Cuentas - Digital | H14: Digital | I14: 32615 | J14: La Montaña Sur 4149, Lampa, Chile | K14: mmartinez@azerta.cl | L14: F | M14: 56973006305 | N14: Monitoreo | O14: Monitoreo | P14: 77.667.011-1 | Q14: SOCIEDAD DE PROFESIONALES AZERTA LTDA | R14: martinez.mariapaz@gmail.com | S14: Lampa | T14: Activo | W14: Paz
A15: 16.282.327-2 | B15: Arancibia Silva Jose Miguel | C15: 16.282.327-2 | D15: Jose Miguel | E15: Arancibia | F15: Silva | G15: Socio Área Digital | H15: Digital | I15: 31661 | J15: Nicosia 7572 | K15: jmarancibia@azerta.cl | L15: M | M15: 56992361278 | N15: Digital | O15: Digital | P15: 76.981.820-0 | Q15: Azerta SpA | R15: jmarancibias@gmail.com | S15: Las Condes | T15: Activo | W15: Jose, JM
A16: 8.344.585-8 | B16: Bofill Carrascal Maria Begoña | C16: 8.344.585-8 | D16: Maria Begoña | E16: Bofill | F16: Carrascal | G16: Socio Director | H16: Comunicaciones | I16: 23896 | J16: Rosa O´Higgins 557 | K16: bbofill@azerta.cl | L16: F | M16: 56993431191 | N16: Comunicaciones | O16: Comunicaciones | P16: 76.981.820-0 | Q16: Azerta SpA | R16: bego.bofill@gmail.com | S16: Las Condes | T16: Activo | W16: Bego
A17: 15.916.585-k | B17: Muñoz Orellana Liliana Andrea | C17: 15.916.585-k | D17: Liliana Andrea | E17: Muñoz | F17: Orellana | G17: Consultor/a - AAPP | H17: Asuntos Públicos | I17: 31049 | J17: Loma La Cruz sur 300, Casa 3 | K17: Lmunoz@azerta.cl | L17: F | M17: 940417291 | N17: Asuntos Públicos | O17: Asuntos Públicos | P17: 76.981.820-0 | Q17: Azerta SpA | R17: lilimunozo85@gmail.com | S17: Lo Barnechea | T17: Activo | W17: Rafa
A18: 9.126.648-2 | B18: Pinto Salazar-Roijers Jenny | C18: 9.126.648-2 | D18: Jenny | E18: Pinto | F18: Salazar-Roijers | G18: Secretaria de Gerencia | H18: Corporate Services | I18: 22926 | J18: AVDA. BELLAVISTA 165 218 | K18: jpinto@azerta.cl | L18: F | M18: 56998205700 | N18: Administración | O18: Administración | P18: 76.981.820-0 | Q18: Azerta SpA | R18: jennypintosr1@gmail.com | S18: Recoleta | T18: Activo | W18: Jenny
A19: 7.465.792-3 | B19: Gálvez Araya Mario Joaquín Gonzalo | C19: 7.465.792-3 | D19: Mario Joaquín Gonzalo | E19: Gálvez | F19: Araya | G19: Consultor/a - Comunicaciones | H19: Comunicaciones | I19: 21293 | J19: La Niña 3020, Las Condes, Chile | K19: mgalvez@azerta.cl | L19: M | M19: 992306635 | N19: Comunicaciones | O19: Comunicaciones | P19: 76.981.820-0 | Q19: Azerta SpA | R19: mariogalveza@icloud.com | S19: Las Condes | T19: Activo
A20: 12.678.387-6 | B20: Pezo Symmer Claudia Edith | C20: 12.678.387-6 | D20: Claudia Edith | E20: Pezo | F20: Symmer | G20: Consultor/a - Prensa | H20: Prensa | I20: 27278 | J20: Padre Mariano 87 Depto. 1206 | K20: cpezo@azerta.cl | L20: F | M20: 994993239 | N20: Prensa | O20: Prensa | P20: 77.667.011-1 | Q20: SOCIEDAD DE PROFESIONALES AZERTA LTDA | R20: claupezito@gmail.com | S20: Providencia | T20: Activo | W20: Clau
A21: 13.432.759-6 | B21: Alarcón Orellana Paulina Violeta | C21: 13.432.759-6 | D21: Paulina Violeta | E21: Alarcón | F21: Orellana | G21: Asistente de Servicios Generales | H21: Corporate Services | I21: 28485 | J21: Monseñor Eyzaguirre 300, Departamento 24 | K21: palarcon@azerta.cl | L21: F | M21: 56999091623 | N21: Administración | O21: Administración | P21: 76.981.820-0 | Q21: Azerta SpA | R21: paulina.alarcon@gmail.com | S21: Ñuñoa | T21: Activo | W21: Pauli
A22: 18.845.158-6 | B22: Alfaro Cornejo Sara Magdalena | C22: 18.845.158-6 | D22: Sara Magdalena | E22: Alfaro | F22: Cornejo | G22: Consultor/a Senior - Comunicaciones | H22: Comunicaciones | I22: 34562 | J22: Flor de Azucena 89, depto 1202, Las Condes, Chile | K22: salfaro@azerta.cl | L22: F | M22: 56962082302 | N22: Comunicaciones | O22: Comunicaciones | P22: 76.981.820-0 | Q22: Azerta SpA | R22: saramgalfaro@gmail.com | S22: Las Condes | T22: Activo | W22: Sari
A23: 16.629.810-5 | B23: Duk Oteíza Christopher Walter | C23: 16.629.810-5 | D23: Christopher Walter | E23: Duk | F23: Oteíza | G23: Jefe de Servicios Generales y TI | H23: Corporate Services | I23: 32209 | J23: Duble Almeyda 1515, depto 604 | K23: cduk@azerta.cl | L23: M | M23: 982065602 | N23: Operaciones | O23: Operaciones | P23: 77.667.011-1 | Q23: SOCIEDAD DE PROFESIONALES AZERTA LTDA | R23: chris.dukot@gmail.com | S23: Ñuñoa | T23: Activo
A24: 9.992.025-4 | B24: Alvarez Henriquez Lidia Rosa | C24: 9.992.025-4 | D24: Lidia Rosa | E24: Alvarez | F24: Henriquez | G24: Auxiliar de Aseo | H24: Corporate Services | I24: 24377 | J24: Claudio Arrau 7861, Depto. 33, torre 8 | K24: lalvarez@azerta.cl | L24: F | M24: 56942454643 | N24: Administración | O24: Administración | P24: 77.667.011-1 | Q24: SOCIEDAD DE PROFESIONALES AZERTA LTDA | R24: lidiaalvarezhenriquez@gmail.com | S24: Pudahuel | T24: Activo | W24: Lidia
A25: 13.253.184-6 | B25: Feres Klenner Camilo | C25: 13.253.184-6 | D25: Camilo | E25: Feres | F25: Klenner | G25: Director de Área de Estudios Sociales y Políticos | H25: Comunicaciones | I25: 28315 | J25: LUIS PEREIRA 810 | K25: cferes@azerta.cl | L25: M | M25: 56971388450 | N25: Comunicaciones | O25: Comunicaciones | P25: 76.981.820-0 | Q25: Azerta SpA | R25: cferes@gmail.com | S25: Ñuñoa | T25: Activo
A26: 11.442.567-2 | B26: Bustos Valenzuela Abraham Segundo | C26: 11.442.567-2 | D26: Abraham Segundo | E26: Bustos | F26: Valenzuela | G26: Gerente de Finanzas | H26: Corporate Services | I26: 25387 | J26: QUEBRADA DE MACUL 8600 CASA 11 | K26: abustos@azerta.cl | L26: M | M26: 56956985578 | N26: Finanzas | O26: Finanzas | P26: 76.981.820-0 | Q26: Azerta SpA | R26: abrahambvalenzuela@yahoo.com | S26: Peñalolén | T26: Activo | W26: Abraham
A27: 20.936.378-k | B27: Chausu Valdés Jesús Alberto | C27: 20.936.378-k | D27: Jesús Alberto | E27: Chausu | F27: Valdés | G27: Ejecutivo en IA - Digital | H27: Digital | I27: 37236 | J27: Las Araucarias, El Bosque, Chile | K27: jchausu@azerta.cl | L27: M | M27: 56976806250 | N27: IA | O27: IA | P27: 77.667.011-1 | Q27: SOCIEDAD DE PROFESIONALES AZERTA LTDA | R27: jesuschausu@gmail.com | S27: El Bosque | T27: Activo
A28: 13.882.744-5 | B28: Villablanca Fernández Gustavo Adolfo | C28: 13.882.744-5 | D28: Gustavo Adolfo | E28: Villablanca | F28: Fernández | G28: Gerente de Personas y Operaciones | H28: Corporate Services | I28: 29449 | J28: Las Vegas 994 | K28: gvillablanca@azerta.cl | L28: M | M28: 990885107 | N28: Personas | O28: Personas | P28: 76.981.820-0 | Q28: Azerta SpA | R28: Gustavo.Villablanca@gmail.com | S28: La Florida | T28: Activo | W28: Gustavo
A29: 12.019.058-k | B29: Galleguillos Martinez Luis Gustavo | C29: 12.019.058-k | D29: Luis Gustavo | E29: Galleguillos | F29: Martinez | G29: Socio Director | H29: Comunicaciones | I29: 26945 | J29: José Rabat 10670, Condominio Los Maderos, Calle los maderos 33 | K29: lgalleguillos@azerta.cl | L29: M | M29: 56966576762 | N29: Comunicaciones | O29: Comunicaciones | P29: 76.981.820-0 | Q29: Azerta SpA | R29: lgallem@gmail.com | S29: Colina | T29: Activo
A30: 19.960.344-2 | B30: Sierralta Fuentealba Benjamín Eugenio | C30: 19.960.344-2 | D30: Benjamín Eugenio | E30: Sierralta | F30: Fuentealba | G30: Consultor/a - Comunicaciones | H30: Comunicaciones | I30: 36085 | J30: Doctor Agustín Andrade 4200 | K30: bsierralta@azerta.cl | L30: M | M30: 976767033 | N30: Comunicaciones | O30: Comunicaciones | P30: 77.667.011-1 | Q30: SOCIEDAD DE PROFESIONALES AZERTA LTDA | R30: Benjamin.sierralta@mail.udp.cl | S30: Ñuñoa | T30: Activo | W30: Benjamín
A31: 14.533.402-0 | B31: Valenzuela Mella Pablo Andrés | C31: 14.533.402-0 | D31: Pablo Andrés | E31: Valenzuela | F31: Mella | G31: Consultor/a Senior - AAPP | H31: Asuntos Públicos | I31: 29060 | J31: Pasaje Alberto 3538 | K31: pvalenzuela@azerta.cl | L31: M | M31: 986589891 | N31: Asuntos Públicos | O31: Asuntos Públicos | P31: 76.981.820-0 | Q31: Azerta SpA | R31: valenzuelamellapablo@gmail.com | S31: Providencia | T31: Activo | W31: Pablo
A32: 17.701.415-k | B32: Concha Valenzuela Loreto | C32: 17.701.415-k | D32: Loreto | E32: Concha | F32: Valenzuela | G32: Consultores Senior - Digital | H32: Digital | I32: 33344 | J32: Ricardo Wagner 2161, depto 1004, La Reina, Chile | K32: lconcha@azerta.cl | L32: F | M32: 56983371510 | N32: Contenidos | O32: Contenidos | P32: 77.667.011-1 | Q32: SOCIEDAD DE PROFESIONALES AZERTA LTDA | R32: lrtconcha@gmail.com | S32: La Reina | T32: Activo | W32: Lore
A33: 20.100.027-0 | B33: Bustos Cárdenas Benjamín Ignacio Abraham | C33: 20.100.027-0 | D33: Benjamín Ignacio Abraham | E33: Bustos | F33: Cárdenas | G33: Asistente de Finanzas y Operaciones | H33: Corporate Services | I33: 36261 | J33: Quebrada de Umallani 1000, Casa N | K33: bbustos@azerta.cl | L33: M | M33: 999744131 | N33: Finanzas | O33: Finanzas | P33: 77.667.011-1 | Q33: SOCIEDAD DE PROFESIONALES AZERTA LTDA | R33: benjaminbustoscardenas@gmail.com | S33: Peñalolén | T33: Activo | W33: Benja
A34: 20.165.239-1 | B34: Herrera Manríquez María Fernanda | C34: 20.165.239-1 | D34: María Fernanda | E34: Herrera | F34: Manríquez | G34: Consultores - Digital | H34: Digital | I34: 36437 | J34: La Gloria 120, depto 307, Las Condes, Chile | K34: fherrera@azerta.cl | L34: F | M34: 99978113 | N34: Diseño | O34: Diseño | P34: 77.667.011-1 | Q34: SOCIEDAD DE PROFESIONALES AZERTA LTDA | R34: fernandaherreramanriquez@gmail.com | S34: Las Condes | T34: Activo | W34: Fernanda
A35: 20.833.546-4 | B35: Terrazas Cortés Paula Sofía | C35: 20.833.546-4 | D35: Paula Sofía | E35: Terrazas | F35: Cortés | G35: Consultores - Digital | H35: Digital | I35: 36852 | J35: Camino del Pregonero 2799 | K35: pterrazas@azerta.cl | L35: F | M35: 954064264 | N35: Contenidos | O35: Contenidos | P35: 77.667.011-1 | Q35: SOCIEDAD DE PROFESIONALES AZERTA LTDA | R35: paulaterrazasc22@gmail.com | S35: Lo Barnechea | T35: Activo | W35: Paula
A36: 19.242.632-4 | B36: Cembrano Schrader Ignacio Stelio | C36: 19.242.632-4 | D36: Ignacio Stelio | E36: Cembrano | F36: Schrader | G36: Ejecutivo/a - Comunicaciones | H36: Comunicaciones | I36: 34934 | J36: Chile España 651 | K36: icembrano@azerta.cl | L36: M | M36: 944865836 | N36: Comunicaciones | O36: Comunicaciones | P36: 77.667.011-1 | Q36: SOCIEDAD DE PROFESIONALES AZERTA LTDA | R36: iscembrano@uc.cl | S36: Ñuñoa | T36: Activo | W36: Ignacio
A37: 13.529.165-k | B37: Abarca Castro Juan Andres | C37: 13.529.165-k | D37: Juan Andres | E37: Abarca | F37: Castro | G37: Director/a - AAPP | H37: Asuntos Públicos | I37: 28914 | J37: Los alelies sur 12, Condominio Las Flores. | K37: jabarca@azerta.cl | L37: M | M37: 56998219599 | N37: Asuntos Públicos | O37: Asuntos Públicos | P37: 76.981.820-0 | Q37: Azerta SpA | R37: juanandres.abarcacastro@gmail.com | S37: Colina | T37: Activo | W37: Juan Andrés
A38: 10.059.648-2 | B38: Dorfman Liberman Natalio Andrés | C38: 10.059.648-2 | D38: Natalio Andrés | E38: Dorfman | F38: Liberman | G38: Consultor/a Senior - AAPP | H38: Asuntos Públicos | I38: 24534 | J38: Suecia 2955 | K38: ndorfman@azerta.cl | L38: M | M38: 98952359 | N38: Asuntos Públicos | O38: Asuntos Públicos | P38: 76.981.820-0 | Q38: Azerta SpA | R38: nadorfma@gmail.com | S38: Ñuñoa | T38: Activo
A39: 18.497.525-4 | B39: Valladares Aravena Javiera Fernanda | C39: 18.497.525-4 | D39: Javiera Fernanda | E39: Valladares | F39: Aravena | G39: Ejecutivo/a de Cuentas - Digital | H39: Digital | I39: 34143 | J39: Los Aviadores 850 | K39: jvalladares@azerta.cl | L39: F | M39: 976605855 | N39: Diseño | O39: Diseño | P39: 77.667.011-1 | Q39: SOCIEDAD DE PROFESIONALES AZERTA LTDA | R39: valladares.javieraf@gmail.com | S39: El Bosque | T39: Activo | W39: Javi
A40: 16.385.148-2 | B40: Palma Lara Andrés Enrique | C40: 16.385.148-2 | D40: Andrés Enrique | E40: Palma | F40: Lara | G40: Junior / Administracion | H40: Corporate Services | I40: 31711 | J40: Calle Flor del Notro 0203, torre a depto 307, Maipú, Chile | K40: apalma@azerta.cl | L40: M | M40: 56988837399 | N40: Administración | O40: Administración | P40: 77.667.011-1 | Q40: SOCIEDAD DE PROFESIONALES AZERTA LTDA | R40: a.palma.lara@gmail.com | S40: Maipú | T40: Activo
A41: 28.759.573-5 | B41: Cobo Paris Irene María | C41: 28.759.573-5 | D41: Irene María | E41: Cobo | F41: Paris | G41: Consultor/a Senior - Comunicaciones | H41: Comunicaciones | I41: 30579 | J41: Camino Otoñal 1368, casa 1 | K41: icobo@azerta.cl | L41: F | N41: Comunicaciones | O41: Comunicaciones | P41: 77.667.011-1 | Q41: SOCIEDAD DE PROFESIONALES AZERTA LTDA | R41: irenemariacobo@gmail.com | S41: Las Condes | T41: Activo | W41: Irene
...
